Workbook

Sheet 2020
A1: Tagged Mussels 2020
A3: Species | B3: Tag # | C3: Tag color | D3: Measurement (MM) | E3: Notes:
A4: A. varicosa | B4: K113 | C4: blue | D4: 22
A5: A. varicosa | B5: K114 | C5: blue | D5: 22
A6: A. varicosa | B6: K115 | C6: blue | D6: 21
A7: A. varicosa | B7: K116 | C7: blue | D7: 19
A8: A. varicosa | B8: K117 | C8: blue | D8: 18
A9: A. varicosa | B9: K118 | C9: blue | D9: 18
A10: A. varicosa | B10: K120 | C10: blue | D10: 15
A11: A. varicosa | B11: K121 | C11: blue | D11: 20
A12: A. varicosa | B12: K122 | C12: blue | D12: 19.5
A13: A. varicosa | B13: K123 | C13: blue | D13: 21
A14: A. varicosa | B14: K124 | C14: blue | D14: 21.5
A15: A. varicosa | B15: K125 | C15: blue | D15: 19
... A59: A. varicosa | B59: K170 | C59: blue | D59: 18
A60: A. varicosa | B60: K171 | C60: blue | D60: 20 | E60: *shell (post-tagging)
A61: A. varicosa | B61: K173 | C61: blue | D61: 19
A62: A. varicosa | B62: K174 | C62: blue | D62: 16
A63: A. varicosa | B63: K175 | C63: blue | D63: 22
A64: A. varicosa | B64: K176 | C64: blue | D64: 19.5
A65: A. varicosa | B65: K177 | C65: blue | D65: 17
A66: A. varicosa | B66: K178 | C66: blue | D66: 16.5
A67: A. varicosa | B67: K179 | C67: blue | D67: 20
A68: A. varicosa | B68: K180 | C68: blue | D68: 19
A69: A. varicosa | B69: K181 | C69: blue | D69: 17
A70: A. varicosa | B70: K182 | C70: blue | D70: 18
A71: A. varicosa | B71: K183 | C71: blue | D71: 16
A72: A. varicosa | B72: K184 | C72: blue | D72: 22
... A243: A. varicosa | B243: K361 | C243: blue | D243: 15
A244: A. varicosa | B244: K362 | C244: blue | D244: 18 | E244: *still at FMCC as of 8/2022
A245: A. varicosa | B245: K363 | C245: blue | D245: 15.5
A246: A. varicosa | B246: K364 | C246: blue | D246: 23
A247: A. varicosa | B247: K365 | C247: blue | D247: 21
A248: A. varicosa | B248: K366 | C248: blue | D248: 20.5
A249: A. varicosa | B249: K367 | C249: blue | D249: 18
A250: A. varicosa | B250: K368 | C250: blue | D250: 17.5
A251: A. varicosa | B251: K370 | C251: blue | D251: 20
A252: A. varicosa | B252: K371 | C252: blue | D252: 18
A253: A. varicosa | B253: K372 | C253: blue | D253: 16
A254: A. varicosa | B254: K373 | C254: blue | D254: 19
...

Sheet 2021
A1: Tagged Mussels Fall 2021
A3: Date | B3: Species | C3: Tag # | D3: Tag color | E3: Measurement (MM) | F3: Notes:
A4: 44481 | B4: Lampsilis cardium | C4: A003 | D4: pink | E4: 13.8
A5: 44481 | B5: Lampsilis cardium | C5: A004 | D5: pink | E5: 14.5
A6: 44481 | B6: Lampsilis cardium | C6: A006 | D6: pink | E6: 14.7
A7: 44481 | B7: Lampsilis cardium | C7: A007 | D7: pink | E7: 16.8
A8: 44481 | B8: Lampsilis cardium | C8: A009 | D8: pink | E8: 22.5
A9: 44481 | B9: Lampsilis cardium | C9: A011 | D9: pink | E9: 15.3
A10: 44481 | B10: Lampsilis cardium | C10: A014 | D10: pink | E10: 19.2
A11: 44481 | B11: Lampsilis cardium | C11: A016 | D11: pink | E11: 13.1
A12: 44481 | B12: Lampsilis cardium | C12: A020 | D12: pink | E12: 16.2
A13: 44481 | B13: Lampsilis cardium | C13: A023 | D13: pink | E13: 15.5
A14: 44481 | B14: Lampsilis cardium | C14: A025 | D14: pink | E14: 18.8
A15: 44481 | B15: Lampsilis cardium | C15: A028 | D15: pink | E15: 17.5
... A220: 44488 | B220: Lampsilis cardium | C220: A323 | D220: pink | E220: 15.2
A221: 44488 | B221: Lampsilis cardium | C221: A324 | D221: pink | E221: 17 | F221: Not released (remaining at FMCC)
A222: 44488 | B222: Lampsilis cardium | C222: A325 | D222: pink | E222: 15.5
A223: 44488 | B223: Lampsilis cardium | C223: A326 | D223: pink | E223: 13.9
A224: 44488 | B224: Lampsilis cardium | C224: A327 | D224: pink | E224: 11.7
A225: 44488 | B225: Lampsilis cardium | C225: A328 | D225: pink | E225: 13.5
A226: 44488 | B226: Lampsilis cardium | C226: A329 | D226: pink | E226: 13.9
A227: 44488 | B227: Lampsilis cardium | C227: A330 | D227: pink | E227: 16.7
A228: 44488 | B228: Lampsilis cardium | C228: A331 | D228: pink | E228: 16.4
A229: 44488 | B229: Lampsilis cardium | C229: A332 | D229: pink | E229: 17.3
A230: 44488 | B230: Lampsilis cardium | C230: A333 | D230: pink | E230: 17.8
A231: 44488 | B231: Lampsilis cardium | C231: A334 | D231: pink | E231: 14.6
A232: 44488 | B232: Lampsilis cardium | C232: A335 | D232: pink | E232: 14.6
A233: 44488 | B233: Lampsilis cardium | C233: A336 | D233: pink | E233: 14.5
... A244: 44488 | B244: Lampsilis cardium | C244: A347 | D244: pink | E244: 12.8
A245: 44489 | B245: Alasmidonta varicosa | C245: A348 | D245: pink | E245: 14.3 | F245: Species ID tentative
A246: 44489 | B246: Lampsilis cardium | C246: A349 | D246: pink | E246: 17
A247: 44489 | B247: Lampsilis cardium | C247: A350 | D247: pink | E247: 16.1
A248: 44489 | B248: Lampsilis cardium | C248: A351 | D248: pink | E248: 15.1
A249: 44489 | B249: Lampsilis cardium | C249: A352 | D249: pink | E249: 12.8
A250: 44489 | B250: Lampsilis cardium | C250: A353 | D250: pink | E250: 13.8
A251: 44489 | B251: Lampsilis cardium | C251: A354 | D251: pink | E251: 18
A252: 44489 | B252: Lampsilis cardium | C252: A355 | D252: pink | E252: 16.4
A253: 44489 | B253: Lampsilis cardium | C253: A356 | D253: pink | E253: 19.2
A254: 44489 | B254: Lampsilis cardium | C254: A357 | D254: pink | E254: 13.6
A255: 44489 | B255: Alasmidonta undulata | C255: A359 | D255: pink | E255: 22.3 | F255: Species ID tentative
...

Sheet 2022 summary
A1: 2022 Mussel Release Summary
A3: Species | B3: Total Count | C3: Min. Size | D3: Max. Size | E3: Average Size
A4: Alasmidonta undulata | B4: ='2022 (8-4)'!C60+'2022 (9-1)'!C23+'2022 (10-7)'!C11+'2022 (10-25)'!C13+1 -> 80 | C4: =MIN('2022 (8-4)'!E7:E59, '2022 (9-1)'!E7:E22,'2022 (10-7)'!E7:E10,'2022 (10-14)'!E7,'2022 (10-25)'!E7:E12) -> 12.9 | D4: =MAX('2022 (8-4)'!E7:E59, '2022 (9-1)'!E7:E22,'2022 (10-7)'!E7:E10,'2022 (10-14)'!E7,'2022 (10-25)'!E7:E12) -> 30 | E4: =AVERAGE('2022 (8-4)'!E60,'2022 (9-1)'!E23,'2022 (10-7)'!E11,'2022 (10-14)'!E7,'2022 (10-25)'!E13) -> 15.352241
A5: Alasmidonta varicosa | B5: ='2022 (8-4)'!C82+'2022 (9-1)'!C28+'2022 (10-25)'!C31 -> 39 | C5: =MIN('2022 (8-4)'!E62:E81,'2022 (9-1)'!E25:E27,'2022 (10-25)'!E15:E30) -> 10.7 | D5: =MAX('2022 (8-4)'!E62:E81,'2022 (9-1)'!E25:E27,'2022 (10-25)'!E15:E30) -> 27.3 | E5: =AVERAGE('2022 (8-4)'!E82,'2022 (9-1)'!E28,'2022 (10-25)'!E31) -> 18.677222
A6: Elliptio complanata | B6: ='2022 (8-4)'!C223+'2022 (10-14)'!C390+'2022 (10-25)'!C254 -> 737 | C6: =MIN('2022 (8-4)'!E85:E222,'2022 (10-14)'!E9:E389,'2022 (10-25)'!E33:E253) -> 10.5 | D6: =MAX('2022 (8-4)'!E85:E222,'2022 (10-14)'!E9:E389,'2022 (10-25)'!E33:E253) -> 44 | E6: =AVERAGE('2022 (8-4)'!E223,'2022 (10-14)'!E390,'2022 (10-25)'!E254) -> 20.21192
A7: Strophitus undulatus | B7: ='2022 (8-4)'!C231+'2022 (9-1)'!C949 -> 24 | C7: =MIN('2022 (8-4)'!E225:E230,'2022 (9-1)'!E932:E948) -> 12.4 | D7: =MAX('2022 (8-4)'!E225:E230,'2022 (9-1)'!E932:E948) -> 33.1 | E7: =AVERAGE('2022 (8-4)'!E231,'2022 (9-1)'!E949) -> 25.015686
A8: Lampsilis cardium | B8: =SUM('2022 (8-4)'!C539,'2022 (9-1)'!C930,'2022 (10-7)'!C794,'2022 (10-14)'!C493,'2022 (10-25)'!C466) -> 4123 | C8: =MIN('2022 (8-4)'!E234:E538,'2022 (9-1)'!E30:E929,'2022 (10-7)'!E13:E793,'2022 (10-14)'!E392:E492,'2022 (10-25)'!E256:E465) -> 9.5 | D8: =MAX('2022 (8-4)'!E234:E538,'2022 (9-1)'!E30:E929,'2022 (10-7)'!E13:E793,'2022 (10-14)'!E392:E492,'2022 (10-25)'!E256:E465) -> 35 | E8: =AVERAGE('2022 (8-4)'!E539,'2022 (9-1)'!E930,'2022 (10-7)'!E794,'2022 (10-14)'!E493,'2022 (10-25)'!E466) -> 16.679093
A10: Grand Total: | B10: =SUM(B4:B8) -> 5003

Sheet 2022 (8-4)
A1: Tagged Mussels Summer 2022
A2: Release Date: | C2: 44777 | E2: Release Site: | F2: South Fork Shenandoah
E3: Conditions: | F3: Sunny weather (74 degrees fahrenheit), clear water, moderately shallow; Discharge= 820 ft3/s
E4: Personnel: | F4: J. Jones, K. Howard, D. Mercer
A6: Date | B6: Species | C6: Tag # | D6: Tag color | E6: Measurement (MM) | F6: Notes:
A7: 44775 | B7: A. undulata | C7: K620 | D7: Blue | E7: 17.2
A8: 44776 | B8: A. undulata | C8: K769 | D8: Blue | E8: 15.6
A9: 44776 | B9: A. undulata | C9: K771 | D9: Blue | E9: 17
A10: 44776 | B10: A. undulata | C10: K772 | D10: Blue | E10: 19
A11: 44776 | B11: A. undulata | C11: K773 | D11: Blue | E11: 17.5
A12: 44776 | B12: A. undulata | C12: K774 | D12: Blue | E12: 16
A13: 44776 | B13: A. undulata | C13: K775 | D13: Blue | E13: 16
A14: 44776 | B14: A. undulata | C14: K776 | D14: Blue | E14: 19.5
A15: 44776 | B15: A. undulata | C15: K777 | D15: Blue | E15: 16
A16: 44776 | B16: A. undulata | C16: K778 | D16: Blue | E16: 18
A17: 44776 | B17: A. undulata | C17: K779 | D17: Blue | E17: 24
A18: 44776 | B18: A. undulata | C18: K780 | D18: Blue | E18: 15
... A59: 44776 | B59: A. undulata | C59: K831 | D59: Blue | E59: 16
B60: Count: | C60: =COUNT(E7:E59) -> 53 | D60: Average: | E60: =AVERAGE(E7:E59) -> 17.392453
A62: 44775 | B62: A. varicosa | C62: K578 | D62: Blue | E62: 23
A63: 44775 | B63: A. varicosa | C63: K595 | D63: Blue | E63: 21.2
A64: 44775 | B64: A. varicosa | C64: K600 | D64: Blue | E64: 23.6
A65: 44775 | B65: A. varicosa | C65: K602 | D65: Blue | E65: 15
A66: 44775 | B66: A. varicosa | C66: K609 | D66: Blue | E66: 27.3
A67: 44775 | B67: A. varicosa | C67: K612 | D67: Blue | E67: 26.1
A68: 44775 | B68: A. varicosa | C68: K616 | D68: Blue | E68: 19.7
A69: 44775 | B69: A. varicosa | C69: K617 | D69: Blue | E69: 22.6
A70: 44775 | B70: A. varicosa | C70: K619 | D70: Blue | E70: 20.2
A71: 44776 | B71: A. varicosa | C71: K770 | D71: Blue | E71: 17.1
A72: 44776 | B72: A. varicosa | C72: K784 | D72: Blue | E72: 17
A73: 44776 | B73: A. varicosa | C73: K786 | D73: Blue | E73: 16.5
... A81: 44776 | B81: A. varicosa | C81: K819 | D81: Blue | E81: 16.5
B82: Count: | C82: =COUNT(E62:E81) -> 20 | D82: Average: | E82: =AVERAGE(E62:E81) -> 20.24
A85: 44775 | B85: E. complanata | C85: K566 | D85: Blue | E85: 36.6
A86: 44775 | B86: E. complanata | C86: K567 | D86: Blue | E86: 32.5
A87: 44775 | B87: E. complanata | C87: K568 | D87: Blue | E87: 34
A88: 44775 | B88: E. complanata | C88: K569 | D88: Blue | E88: 32.2
A89: 44775 | B89: E. complanata | C89: K570 | D89: Blue | E89: 31.3
A90: 44775 | B90: E. complanata | C90: K571 | D90: Blue | E90: 33.4
A91: 44775 | B91: E. complanata | C91: K572 | D91: Blue | E91: 31.8
...

Sheet 2022 (9-1)
A1: Tagged Mussels Summer 2022
A2: Release Date: | C2: 44805 | E2: Release Site: | F2: South Fork Shenandoah
E3: Conditions: | F3: Sunny weather (79 degrees fahrenheit), clear water, moderately shallow; Discharge= 440 ft3/s
E4: Personnel: | F4: I. Boyce, K. Howard, D. Mercer
A6: Date | B6: Species | C6: Tag # | D6: Tag color | E6: Measurement (MM) | F6: Notes:
A7: 44796 | B7: A. undulata | C7: X096 | D7: Blue | E7: 21
A8: 44796 | B8: A. undulata | C8: X097 | D8: Blue | E8: 16
A9: 44796 | B9: A. undulata | C9: X098 | D9: Blue | E9: 13.6
A10: 44796 | B10: A. undulata | C10: X099 | D10: Blue | E10: 13
A11: 44796 | B11: A. undulata | C11: X100 | D11: Blue | E11: 13.7
A12: 44796 | B12: A. undulata | C12: X101 | D12: Blue | E12: 13.3
A13: 44796 | B13: A. undulata | C13: X158 | D13: Blue | E13: 13.5
A14: 44796 | B14: A. undulata | C14: X159 | D14: Blue | E14: 16
A15: 44796 | B15: A. undulata | C15: X160 | D15: Blue | E15: 14.9
A16: 44796 | B16: A. undulata | C16: X161 | D16: Blue | E16: 13.1
A17: 44796 | B17: A. undulata | C17: X162 | D17: Blue | E17: 15.2
A18: 44796 | B18: A. undulata | C18: X163 | D18: Blue | E18: 15.5
... A22: 44798 | B22: A. undulata | C22: X440 | D22: Blue | E22: 30
B23: Count: | C23: =COUNTA(C7:C22) -> 16 | D23: Average: | E23: =AVERAGE(E7:E22) -> 16.16875
A25: 44798 | B25: A. varicosa | C25: X437 | D25: Blue | E25: 21
A26: 44798 | B26: A. varicosa | C26: X438 | D26: Blue | E26: 23.5
A27: 44798 | B27: A. varicosa | C27: K362 | D27: Blue | E27: 23.5 | F27: Had been previously tagged but had not been released yet.
B28: Count: | C28: =COUNTA(C25:C27) -> 3 | D28: Average: | E28: =AVERAGE(E25:E27) -> 22.666667
A30: 44796 | B30: L. cardium | C30: X089 | D30: Blue | E30: 14.8
A31: 44796 | B31: L. cardium | C31: X090 | D31: Blue | E31: 17
A32: 44796 | B32: L. cardium | C32: X091 | D32: Blue | E32: 13
A33: 44796 | B33: L. cardium | C33: X092 | D33: Blue | E33: 13
A34: 44796 | B34: L. cardium | C34: X093 | D34: Blue | E34: 15
A35: 44796 | B35: L. cardium | C35: X094 | D35: Blue | E35: 20
A36: 44796 | B36: L. cardium | C36: X095 | D36: Blue | E36: 13.9
A37: 44796 | B37: L. cardium | C37: X102 | D37: Blue | E37: 30
A38: 44796 | B38: L. cardium | C38: X103 | D38: Blue | E38: 14.8
A39: 44796 | B39: L. cardium | C39: X104 | D39: Blue | E39: 13
A40: 44796 | B40: L. cardium | C40: X105 | D40: Blue | E40: 18
A41: 44796 | B41: L. cardium | C41: X106 | D41: Blue | E41: 16.1
... A71: 44796 | B71: L. cardium | C71: X136 | D71: Blue | E71: 13.7
A72: 44796 | B72: L. cardium | C72: X137 | D72: Blue | E72: 14 | F72: *shell (post-tagging)
A73: 44796 | B73: L. cardium | C73: X138 | D73: Blue | E73: 13.1
A74: 44796 | B74: L. cardium | C74: X139 | D74: Blue | E74: 14.8
A75: 44796 | B75: L. cardium | C75: X140 | D75: Blue | E75: 14.9
...

Sheet 2022 (10-7)
A1: Tagged Mussels Summer 2022
A2: Release Date: | C2: 44841 | E2: Release Site: | F2: South Fork Shenandoah (38.84413, -78.33766)
E3: Conditions: | F3: Sunny weather (75 degrees fahrenheit), clear water, moderately shallow; Discharge= 873 ft3/s
E4: Personnel: | F4: I. Boyce, K. Howard, D. Mercer
A6: Date | B6: Species | C6: Tag # | D6: Tag color | E6: Measurement (MM) | F6: Notes:
A7: 44833 | B7: A. undulata | C7: B918 | D7: Blue | E7: 15.3
A8: 44833 | B8: A. undulata | C8: B919 | D8: Blue | E8: 13.7
A9: 44833 | B9: A. undulata | C9: B920 | D9: Blue | E9: 15.2
A10: 44833 | B10: A. undulata | C10: B921 | D10: Blue | E10: 15.6
B11: Count: | C11: 4 | D11: Average: | E11: =AVERAGE(E7:E10) -> 14.95
A13: 44826 | B13: L. cardium | C13: B025 | D13: Blue | E13: 18.1
A14: 44826 | B14: L. cardium | C14: B026 | D14: Blue | E14: 17.4
A15: 44826 | B15: L. cardium | C15: B027 | D15: Blue | E15: 16.6
A16: 44826 | B16: L. cardium | C16: B028 | D16: Blue | E16: 17.1
A17: 44826 | B17: L. cardium | C17: B029 | D17: Blue | E17: 22
A18: 44826 | B18: L. cardium | C18: B030 | D18: Blue | E18: 18.7
A19: 44826 | B19: L. cardium | C19: B031 | D19: Blue | E19: 16.6
A20: 44826 | B20: L. cardium | C20: B032 | D20: Blue | E20: 19.1
A21: 44826 | B21: L. cardium | C21: B033 | D21: Blue | E21: 15.8
A22: 44826 | B22: L. cardium | C22: B034 | D22: Blue | E22: 18.2
A23: 44826 | B23: L. cardium | C23: B035 | D23: Blue | E23: 17.9
A24: 44826 | B24: L. cardium | C24: B036 | D24: Blue | E24: 20.2
... A371: 44830 | B371: L. cardium | C371: B383 | D371: Blue | E371: 16.1
A372: 44830 | B372: L. cardium | C372: B384 | D372: Blue | E372: 12.6 | F372: *shell (post-tagging)
A373: 44830 | B373: L. cardium | C373: B385 | D373: Blue | E373: 14.2
A374: 44830 | B374: L. cardium | C374: B386 | D374: Blue | E374: 14.4
A375: 44830 | B375: L. cardium | C375: B387 | D375: Blue | E375: 13
A376: 44830 | B376: L. cardium | C376: B388 | D376: Blue | E376: 13.8
A377: 44830 | B377: L. cardium | C377: B389 | D377: Blue | E377: 12.8
A378: 44830 | B378: L. cardium | C378: B390 | D378: Blue | E378: 17.7
A379: 44830 | B379: L. cardium | C379: B391 | D379: Blue | E379: 17.7
A380: 44830 | B380: L. cardium | C380: B392 | D380: Blue | E380: 17
A381: 44830 | B381: L. cardium | C381: B393 | D381: Blue | E381: 16.4
A382: 44830 | B382: L. cardium | C382: B394 | D382: Blue | E382: 15.2
A383: 44830 | B383: L. cardium | C383: B395 | D383: Blue | E383: 13.3
A384: 44830 | B384: L. cardium | C384: B396 | D384: Blue | E384: 15.3
... A407: 44830 | B407: L. cardium | C407: B419 | D407: Blue | E407: 11.9
A408: 44830 | B408: L. cardium | C408: B420 | D408: Blue | E408: 11.4 | F408: *Left behind at FMCC; released on 10/25/22 with later tagged mussels
A409: 44830 | B409: L. cardium | C409: B421 | D409: Blue | E409: 13.2
A410: 44830 | B410: L. cardium | C410: B422 | D410: Blue | E410: 15.5
...

Sheet 2022 (10-14)
A1: Tagged Mussels October 2022
A2: Release Date: | C2: 44848 | E2: Release Site: | F2: South Fork Shenandoah (38.84508, -78.33878)
E3: Conditions: | F3: Sunny weather (72 degrees Fahrenheit), clear water, Discharge= 536 ft3/s
E4: Personnel: | F4: I. Boyce, K. Howard
A6: Date | B6: Species | C6: Tag # | D6: Tag color | E6: Measurement (MM) | F6: Notes:
A7: 44847 | B7: A. undulata | C7: C061 | D7: Blue | E7: 13.1
A9: 44833 | B9: E. complanata | C9: B806 | D9: Blue | E9: 20.8
A10: 44833 | B10: E. complanata | C10: B807 | D10: Blue | E10: 23
A11: 44833 | B11: E. complanata | C11: B808 | D11: Blue | E11: 20.9 | F11: *Left behind at FMCC; still unreleased as of 11/11/2024
A12: 44833 | B12: E. complanata | C12: B809 | D12: Blue | E12: 18.1
A13: 44833 | B13: E. complanata | C13: B810 | D13: Blue | E13: 16.7
A14: 44833 | B14: E. complanata | C14: B811 | D14: Blue | E14: 16.7
A15: 44833 | B15: E. complanata | C15: B812 | D15: Blue | E15: 16.5
A16: 44833 | B16: E. complanata | C16: B813 | D16: Blue | E16: 16.1
A17: 44833 | B17: E. complanata | C17: B814 | D17: Blue | E17: 15.6
A18: 44833 | B18: E. complanata | C18: B815 | D18: Blue | E18: 15.6
A19: 44833 | B19: E. complanata | C19: B816 | D19: Blue | E19: 15.8
A20: 44833 | B20: E. complanata | C20: B817 | D20: Blue | E20: 14.3
A21: 44833 | B21: E. complanata | C21: B818 | D21: Blue | E21: 13.7 | F21: *Left behind at FMCC; released on 10/25/22 with later tagged mussels
A22: 44833 | B22: E. complanata | C22: B819 | D22: Blue | E22: 15.2
A23: 44833 | B23: E. complanata | C23: B820 | D23: Blue | E23: 15.2
A24: 44833 | B24: E. complanata | C24: B821 | D24: Blue | E24: 14.3
A25: 44833 | B25: E. complanata | C25: B822 | D25: Blue | E25: 15.2
A26: 44833 | B26: E. complanata | C26: B823 | D26: Blue | E26: 14.4
A27: 44833 | B27: E. complanata | C27: B824 | D27: Blue | E27: 15.5
A28: 44833 | B28: E. complanata | C28: B825 | D28: Blue | E28: 14.5
A29: 44833 | B29: E. complanata | C29: B826 | D29: Blue | E29: 13.3
A30: 44833 | B30: E. complanata | C30: B827 | D30: Blue | E30: 13.6
A31: 44833 | B31: E. complanata | C31: B828 | D31: Blue | E31: 23
A32: 44833 | B32: E. complanata | C32: B829 | D32: Blue | E32: 19.8
A33: 44833 | B33: E. complanata | C33: B830 | D33: Blue | E33: 18
A34: 44833 | B34: E. complanata | C34: B831 | D34: Blue | E34: 18.1
A35: 44833 | B35: E. complanata | C35: B832 | D35: Blue | E35: 18.9 | F35: *Left behind at FMCC; still unreleased as of 11/11/2024
A36: 44833 | B36: E. complanata | C36: B833 | D36: Blue | E36: 17.8
A37: 44833 | B37: E. complanata | C37: B834 | D37: Blue | E37: 17.5
A38: 44833 | B38: E. complanata | C38: B835 | D38: Blue | E38: 17.4
A39: 44833 | B39: E. complanata | C39: B836 | D39: Blue | E39: 16.7
A40: 44833 | B40: E. complanata | C40: B837 | D40: Blue | E40: 16.6
A41: 44833 | B41: E. complanata | C41: B838 | D41: Blue | E41: 16.2
A42: 44833 | B42: E. complanata | C42: B839 | D42: Blue | E42: 16
...

Sheet 2022 (10-25)
A1: Tagged Mussels October 2022
A2: Release Date: | C2: 44859 | E2: Release Site: | F2: South Fork Shenandoah (38.84520, -78.33906)
E3: Conditions: | F3: Sunny and clear (65 degrees fahrenheit), water low and clear ~15 degrees celsius, Discharge= 450 ft3/s
E4: Personnel: | F4: K. Howard, I. Boyce
A6: Date | B6: Species | C6: Tag # | D6: Tag color | E6: Measurement (MM) | F6: Notes:
A7: 44852 | B7: A. undulata | C7: C192 | D7: Blue | E7: 16.4
A8: 44852 | B8: A. undulata | C8: C193 | D8: Blue | E8: 15.7
A9: 44852 | B9: A. undulata | C9: C194 | D9: Blue | E9: 14.1
A10: 44858 | B10: A. undulata | C10: C490 | D10: Blue | E10: 14.7
A11: 44858 | B11: A. undulata | C11: C491 | D11: Blue | E11: 14.6
A12: 44858 | B12: A. undulata | C12: C492 | D12: Blue | E12: 15.4
B13: Count: | C13: =COUNTA(C7:C12) -> 6 | D13: Average: | E13: =AVERAGE(E7:E12) -> 15.15
A15: 44858 | B15: A. varicosa | C15: C493 | D15: Blue | E15: 12.6
A16: 44858 | B16: A. varicosa | C16: C494 | D16: Blue | E16: 14.5
A17: 44858 | B17: A. varicosa | C17: C495 | D17: Blue | E17: 13.5
A18: 44858 | B18: A. varicosa | C18: C496 | D18: Blue | E18: 13.8
A19: 44858 | B19: A. varicosa | C19: C497 | D19: Blue | E19: 14.1
A20: 44858 | B20: A. varicosa | C20: C498 | D20: Blue | E20: 13.7
A21: 44858 | B21: A. varicosa | C21: C499 | D21: Blue | E21: 15.5
A22: 44858 | B22: A. varicosa | C22: C500 | D22: Blue | E22: 14.4
A23: 44858 | B23: A. varicosa | C23: C501 | D23: Blue | E23: 13.6
A24: 44858 | B24: A. varicosa | C24: C502 | D24: Blue | E24: 12.9
A25: 44858 | B25: A. varicosa | C25: C503 | D25: Blue | E25: 13.1
A26: 44858 | B26: A. varicosa | C26: C504 | D26: Blue | E26: 11.6
... A30: 44858 | B30: A. varicosa | C30: C508 | D30: Blue | E30: 10.7
B31: Count: | C31: =COUNTA(C15:C30) -> 16 | D31: Average: | E31: =AVERAGE(E15:E30) -> 13.125
A33: 44852 | B33: E. complanata | C33: B818 | D33: Blue | E33: 13.9 | F33: *Previously tagged but left behind at FMCC; re-measured and released 10/25/22 with newly tagged mussels
A34: 44852 | B34: E. complanata | C34: B855 | D34: Blue | E34: 16 | F34: *Previously tagged but left behind at FMCC; re-measured and released 10/25/22 with newly tagged mussels
A35: 44852 | B35: E. complanata | C35: C195 | D35: Blue | E35: 20.8
A36: 44852 | B36: E. complanata | C36: C196 | D36: Blue | E36: 20
A37: 44852 | B37: E. complanata | C37: C197 | D37: Blue | E37: 23.6
A38: 44852 | B38: E. complanata | C38: C198 | D38: Blue | E38: 17.5
A39: 44852 | B39: E. complanata | C39: C199 | D39: Blue | E39: 18.3
A40: 44852 | B40: E. complanata | C40: C200 | D40: Blue | E40: 19
A41: 44852 | B41: E. complanata | C41: C201 | D41: Blue | E41: 17.1
A42: 44852 | B42: E. complanata | C42: C202 | D42: Blue | E42: 15
A43: 44852 | B43: E. complanata | C43: C203 | D43: Blue | E43: 15.5
A44: 44852 | B44: E. complanata | C44: C204 | D44: Blue | E44: 13.2
A45: 44852 | B45: E. complanata | C45: C205 | D45: Blue | E45: 12.2
A46: 44852 | B46: E. complanata | C46: C206 | D46: Blue | E46: 12.5
...

Sheet 2023 Summary
A1: 2023 Mussel Release Summary
A3: Species | B3: Total Count | C3: Min. Size | D3: Max. Size | E3: Average Size
A4: Alasmidonta varicosa | B4: ='2023 (10-11)'!C57 -> 372 | C4: =MIN('2023 (10-11)'!E7:E56) -> 10 | D4: =MAX('2023 (10-11)'!E7:E56) -> 26 | E4: ='2023 (10-11)'!E57 -> 15.489796
A5: Elliptio complanata | B5: ='2023 (10-11)'!C658 -> 820 | C5: =MIN('2023 (10-11)'!E59:E657) -> 10 | D5: =MAX('2023 (10-11)'!E59:E657) -> 48 | E5: ='2023 (10-11)'!E658 -> 15.02
A6: Elliptio fisheriana | B6: ='2023 (10-11)'!C675 -> 355 | C6: =MIN('2023 (10-11)'!E660:E674) -> 12 | D6: =MAX('2023 (10-11)'!E660:E674) -> 19 | E6: ='2023 (10-11)'!E675 -> 15.333333
A7: Lampsilis cardium | B7: ='2023 (10-11)'!C999+'2023 (10-19)'!C415 -> 3064 | C7: =MIN('2023 (10-11)'!E677:E998,'2023 (10-19)'!E7:E414) -> 8 | D7: =MAX('2023 (10-11)'!E677:E998,'2023 (10-19)'!E7:E414) -> 25 | E7: =AVERAGE('2023 (10-11)'!E999,'2023 (10-19)'!E415) -> 15.022838
A9: Grand Total: | B9: =SUM(B4:B7) -> 4611

Sheet 2023 (10-11)
A1: Tagged Mussels October 2023
A2: Release Date: | C2: 45210 | E2: Release Site:
E3: Conditions: | F3: Water 15 degrees celsius
E4: Personnel: | F4: J. Jones, A. Anderson
A6: Date | B6: Species | C6: Tag # | D6: Tag color | E6: Measurement (MM) | F6: Notes:
A7: 45208 | B7: Alasmidonta varicosa | C7: A693 | D7: Green | E7: 17
A8: 45208 | B8: Alasmidonta varicosa | C8: A694 | D8: Green | E8: 18
A9: 45208 | B9: Alasmidonta varicosa | C9: A695 | D9: Green | E9: 17
A10: 45208 | B10: Alasmidonta varicosa | C10: A696 | D10: Green | E10: 17
A11: 45208 | B11: Alasmidonta varicosa | C11: A697 | D11: Green | E11: 16
A12: 45208 | B12: Alasmidonta varicosa | C12: A698 | D12: Green | E12: 16
A13: 45208 | B13: Alasmidonta varicosa | C13: A699 | D13: Green | E13: 16
A14: 45208 | B14: Alasmidonta varicosa | C14: A700 | D14: Green | E14: 16
A15: 45208 | B15: Alasmidonta varicosa | C15: A701 | D15: Green | E15: 17
A16: 45208 | B16: Alasmidonta varicosa | C16: A702 | D16: Green | E16: 21
A17: 45208 | B17: Alasmidonta varicosa | C17: A703 | D17: Green | E17: 17
A18: 45208 | B18: Alasmidonta varicosa | C18: A704 | D18: Green | F18: *Shell (post tagging)
A19: 45208 | B19: Alasmidonta varicosa | C19: A705 | D19: Green | E19: 20
A20: 45208 | B20: Alasmidonta varicosa | C20: A706 | D20: Green | E20: 18
A21: 45208 | B21: Alasmidonta varicosa | C21: A707 | D21: Green | E21: 17
A22: 45208 | B22: Alasmidonta varicosa | C22: A708 | D22: Green | E22: 17
A23: 45208 | B23: Alasmidonta varicosa | C23: A794 | D23: Green | E23: 26
A24: 45208 | B24: Alasmidonta varicosa | C24: A795 | D24: Green | E24: 17
A25: 45208 | B25: Alasmidonta varicosa | C25: A796 | D25: Green | E25: 21
A26: 45208 | B26: Alasmidonta varicosa | C26: A797 | D26: Green | E26: 14
A27: 45208 | B27: Alasmidonta varicosa | C27: A798 | D27: Green | E27: 16
A28: 45208 | B28: Alasmidonta varicosa | C28: A799 | D28: Green | E28: 14
A29: 45208 | B29: Alasmidonta varicosa | C29: A800 | D29: Green | E29: 12
A30: 45208 | B30: Alasmidonta varicosa | C30: A801 | D30: Green | E30: 25
... A56: 45208 | B56: Alasmidonta varicosa | C56: No # | D56: Green | E56: 11
B57: Count: | C57: 372 | D57: Average: | E57: =AVERAGE(E7:E56) -> 15.489796 | F57: *372 Alasmidonta varicosa released in total; 35 of the largest ones tagged and measured, 1 mussel was shown to be shell post-tagging, 15 were measured as a sample and tagged with green tags with no number, remainder tagged with green tags without numbers.
A59: 45182 | B59: Elliptio complanata | C59: A082 | D59: Green | E59: 18
A60: 45183 | B60: Elliptio complanata | C60: A098 | D60: Green | E60: 20
A61: 45187 | B61: Elliptio complanata | C61: A153 | D61: Green | E61: 24
A62: 45187 | B62: Elliptio complanata | C62: A154 | D62: Green | E62: 21
A63: 45187 | B63: Elliptio complanata | C63: A155 | D63: Green | E63: 22
A64: 45187 | B64: Elliptio complanata | C64: A156 | D64: Green | E64: 20
A65: 45187 | B65: Elliptio complanata | C65: A157 | D65: Green | E65: 15
A66: 45187 | B66: Elliptio complanata | C66: A158 | D66: Green | E66: 20
A67: 45187 | B67: Elliptio complanata | C67: A159 | D67: Green | E67: 18 | F67: *Shell (post tagging)
...

Sheet 2023 (10-19)
A1: Tagged Mussels October 2023
A2: Release Date: | C2: 45218 | E2: Release Site: | F2: Hazard Mill Island, Shenandoah River
E3: Conditions: | F3: Water 15 degrees celsius
E4: Personnel: | F4: J. Jones, A. Anderson
A6: Date | B6: Species | C6: Tag # | D6: Tag color | E6: Measurement (MM) | F6: Notes:
A7: 45210 | B7: Lampsilis cardium | C7: A873 | D7: Green | E7: 14
A8: 45210 | B8: Lampsilis cardium | C8: A874 | D8: Green | E8: 14
A9: 45210 | B9: Lampsilis cardium | C9: A875 | D9: Green | E9: 14
A10: 45210 | B10: Lampsilis cardium | C10: A876 | D10: Green | E10: 14
A11: 45210 | B11: Lampsilis cardium | C11: A877 | D11: Green | E11: 13
A12: 45210 | B12: Lampsilis cardium | C12: A878 | D12: Green | E12: 13
A13: 45210 | B13: Lampsilis cardium | C13: A879 | D13: Green | E13: 15
A14: 45210 | B14: Lampsilis cardium | C14: A880 | D14: Green | E14: 14
A15: 45210 | B15: Lampsilis cardium | C15: A881 | D15: Green | E15: 14
A16: 45210 | B16: Lampsilis cardium | C16: A882 | D16: Green | E16: 15
A17: 45210 | B17: Lampsilis cardium | C17: A883 | D17: Green | E17: 15
A18: 45210 | B18: Lampsilis cardium | C18: A884 | D18: Green | E18: 13
... A260: 45217 | B260: Lampsilis cardium | C260: B186 | D260: Green | E260: 18
A261: 45217 | B261: Lampsilis cardium | C261: B187 | D261: Green | E261: 16 | F261: *Shell (post-tagging)
A262: 45217 | B262: Lampsilis cardium | C262: B188 | D262: Green | E262: 14
A263: 45217 | B263: Lampsilis cardium | C263: B189 | D263: Green | E263: 18
A264: 45217 | B264: Lampsilis cardium | C264: B190 | D264: Green | E264: 16
A265: 45217 | B265: Lampsilis cardium | C265: B191 | D265: Green | E265: 17
A266: 45217 | B266: Lampsilis cardium | C266: B192 | D266: Green | E266: 16
A267: 45217 | B267: Lampsilis cardium | C267: B193 | D267: Green | E267: 16
A268: 45217 | B268: Lampsilis cardium | C268: B194 | D268: Green | E268: 16
A269: 45217 | B269: Lampsilis cardium | C269: B195 | D269: Green | E269: 15
A270: 45217 | B270: Lampsilis cardium | C270: B196 | D270: Green | E270: 17
A271: 45217 | B271: Lampsilis cardium | C271: B197 | D271: Green | E271: 18
A272: 45217 | B272: Lampsilis cardium | C272: B198 | D272: Green | E272: 16
A273: 45217 | B273: Lampsilis cardium | C273: B199 | D273: Green | E273: 18
... A279: 45217 | B279: Lampsilis cardium | C279: B205 | D279: Green | E279: 17
A280: 45210 | B280: Lampsilis cardium | D280: Black glue | E280: 11
A281: 45210 | B281: Lampsilis cardium | D281: Black glue | E281: 13
A282: 45210 | B282: Lampsilis cardium | D282: Black glue | E282: 13
A283: 45210 | B283: Lampsilis cardium | D283: Black glue | E283: 13
A284: 45210 | B284: Lampsilis cardium | D284: Black glue | E284: 12
A285: 45210 | B285: Lampsilis cardium | D285: Black glue | E285: 12
A286: 45210 | B286: Lampsilis cardium | D286: Black glue | E286: 13
A287: 45210 | B287: Lampsilis cardium | D287: Black glue | E287: 11
...

Sheet 2024 Summary
A1: 2024 Mussel Release Summary
A3: Species | B3: Total Count | C3: Min. Size | D3: Max. Size | E3: Average Size
A4: Alasmidonta varicosa | B4: 70 | C4: =MIN('2024'!E8:E80) -> 18 | D4: =MAX('2024'!E8:E80) -> 25 | E4: ='2024'!E81 -> 20.616438
A5: Elliptio complanata | B5: 443 | C5: =MIN('2024'!E82:E530) -> 15 | D5: =MAX('2024'!E82:E530) -> 37 | E5: ='2024'!E531 -> 22.768374
A6: Elliptio fisheriana | B6: 62 | C6: =MIN('2024'!E532:E627) -> 18 | D6: =MAX('2024'!E532:E627) -> 31 | E6: ='2024'!E628 -> 24.885417
A7: Lampsilis cardium (tagged) | B7: 465 | C7: =MIN('2024'!E629:E1100) -> 14 | D7: =MAX('2024'!E629:E1100) -> 36 | E7: ='2024'!E1101 -> 20.169492
A8: Lampsilis cardium (marked with black glue) | B8: 2148 | C8: =MIN('2024'!E1102:E1257) -> 14 | D8: =MAX('2024'!E1102:E1257) -> 30 | E8: ='2024'!E1258 -> 20.205128
A9: Lampsilis radiata | B9: 27 | C9: =MIN('2024'!E1259:E1286) -> 28 | D9: =MAX('2024'!E1259:E1286) -> 41 | E9: ='2024'!E1287 -> 35.321429
A10: Ligumia nasuta | B10: 1618 | C10: =MIN('2024'!E1288:E2947) -> 17 | D10: =MAX('2024'!E1288:E2947) -> 46 | E10: ='2024'!E2948 -> 25.746386
A11: Strophitus undulatus | B11: 40 | C11: =MIN('2024'!E2949:E2988) -> 20 | D11: =MAX('2024'!E2949:E2988) -> 31 | E11: ='2024'!E2989 -> 26.825
A12: Grand Total: | B12: =SUM(B4:B11) -> 4873

Sheet 2024
A1: Tagged Mussels September 2024
A2: Release Date: | C2: 45582 | E2: Release Site: | F2: South Fork Shenandoah River at State Park canoe launch, left descending bank
E3: Conditions: | F3: Sunny, 56 degrees fahrenheit. Water clear
E4: Personnel: | F4: J. Jones, P. Sullivan, A. Condon, K. Howard
A6: Date | B6: Species | C6: Tag # | D6: Tag color | E6: Measurement (MM) | F6: Notes:
A8: 45546 | B8: Alasmidonta varicosa | C8: B763 | D8: Green | E8: 20
A9: 45546 | B9: Alasmidonta varicosa | C9: B764 | D9: Green | E9: 20
A10: 45546 | B10: Alasmidonta varicosa | C10: B765 | D10: Green | E10: 21
A11: 45546 | B11: Alasmidonta varicosa | C11: B766 | D11: Green | E11: 18
A12: 45546 | B12: Alasmidonta varicosa | C12: B767 | D12: Green | E12: 21
A13: 45546 | B13: Alasmidonta varicosa | C13: B768 | D13: Green | E13: 19
A14: 45546 | B14: Alasmidonta varicosa | C14: B769 | D14: Green | E14: 21
A15: 45546 | B15: Alasmidonta varicosa | C15: B770 | D15: Green | E15: 21
A16: 45546 | B16: Alasmidonta varicosa | C16: B771 | D16: Green | E16: 19 | F16: *Shell (post tagging)
A17: 45546 | B17: Alasmidonta varicosa | C17: B772 | D17: Green | E17: 18
A18: 45546 | B18: Alasmidonta varicosa | C18: B773 | D18: Green | E18: 18
A19: 45546 | B19: Alasmidonta varicosa | C19: B774 | D19: Green | E19: 20
A20: 45546 | B20: Alasmidonta varicosa | C20: B775 | D20: Green | E20: 20 | F20: *Shell (post tagging)
A21: 45546 | B21: Alasmidonta varicosa | C21: B776 | D21: Green | E21: 20
A22: 45546 | B22: Alasmidonta varicosa | C22: B777 | D22: Green | E22: 19
A23: 45546 | B23: Alasmidonta varicosa | C23: B778 | D23: Green | E23: 23
A24: 45546 | B24: Alasmidonta varicosa | C24: B779 | D24: Green | E24: 24
A25: 45546 | B25: Alasmidonta varicosa | C25: B780 | D25: Green | E25: 19
A26: 45546 | B26: Alasmidonta varicosa | C26: B781 | D26: Green | E26: 22
A27: 45546 | B27: Alasmidonta varicosa | C27: B782 | D27: Green | E27: 21
A28: 45546 | B28: Alasmidonta varicosa | C28: B783 | D28: Green | E28: 24
A29: 45546 | B29: Alasmidonta varicosa | C29: B784 | D29: Green | E29: 20
A30: 45546 | B30: Alasmidonta varicosa | C30: B785 | D30: Green | E30: 24
A31: 45546 | B31: Alasmidonta varicosa | C31: B786 | D31: Green | E31: 18
A32: 45546 | B32: Alasmidonta varicosa | C32: B787 | D32: Green | E32: 25
... A69: 45555 | B69: Alasmidonta varicosa | C69: C800 | D69: Green | E69: 21
A70: 45555 | B70: Alasmidonta varicosa | C70: C801 | D70: Green | E70: 23 | F70: *Accidentally kept behind at lab and not released
A71: 45555 | B71: Alasmidonta varicosa | C71: C802 | D71: Green | E71: 24
A72: 45555 | B72: Alasmidonta varicosa | C72: C803 | D72: Green | E72: 20
A73: 45555 | B73: Alasmidonta varicosa | C73: C804 | D73: Green | E73: 19
A74: 45555 | B74: Alasmidonta varicosa | C74: C805 | D74: Green | E74: 20
A75: 45555 | B75: Alasmidonta varicosa | C75: C806 | D75: Green | E75: 20
A76: 45555 | B76: Alasmidonta varicosa | C76: C807 | D76: Green | E76: 19
A77: 45555 | B77: Alasmidonta varicosa | C77: C808 | D77: Green | E77: 24
A78: 45555 | B78: Alasmidonta varicosa | C78: C809 | D78: Green | E78: 22
...

Sheet 2025 Summary
A1: 2025 Mussel Release Summary
A3: Species | B3: Total Count | C3: Min. Size | D3: Max. Size | E3: Average Size
A4: Alasmidonta varicosa | B4: 77 | C4: =MIN('2025'!E7:E84) -> 19 | D4: =MAX('2025'!E7:E84) -> 29 | E4: =AVERAGE('2025'!E7:E84) -> 23.282051
A5: Elliptio complanata | B5: 7 | C5: =MIN('2025'!E86:E92) -> 19 | D5: =MAX('2025'!E86:E92) -> 66 | E5: =AVERAGE('2025'!E86:E92) -> 29.857143
A6: Elliptio fisheriana | B6: 153 | C6: =MIN('2025'!E94:E246) -> 22 | D6: =MAX('2025'!E94:E246) -> 39 | E6: =AVERAGE('2025'!E94:E246) -> 32.522876
A7: Lampsilis cardium | B7: 2089 | C7: =MIN('2025'!E248:E364) -> 14 | D7: =MAX('2025'!E248:E364) -> 29 | E7: =AVERAGE('2025'!E248:E364) -> 19.145299
A8: Lampsilis radiata | B8: 125 | C8: =MIN('2025'!E366:E490) -> 21 | D8: =MAX('2025'!E366:E490) -> 57 | E8: =AVERAGE('2025'!E366:E490) -> 28.888
A9: Ligumia nasuta | B9: 76 | C9: =MIN('2025'!E492:E569) -> 18 | D9: =MAX('2025'!E492:E569) -> 37 | E9: =AVERAGE('2025'!E492:E569) -> 24.705128
A10: Strophitus undulatus | B10: 41 | C10: =MIN('2025'!E571:E612) -> 18 | D10: =MAX('2025'!E571:E612) -> 36 | E10: =AVERAGE('2025'!E571:E612) -> 24.833333
A11: Grand Total: | B11: =SUM(B4:B10) -> 2568

Sheet 2025
A1: Tagged Mussels September 2025
A2: Release Date: | B2: 45945 | E2: Release Site: | F2: South Fork Shenandoa River, 38.852839, -78.319643
E3: Conditions: | F3: 70°F, sunny with few clouds. Water clear, 15.5°C
E4: Personnel: | F4: A. Anderson, D. Mercer
A6: Date | B6: Species | C6: Tag # | D6: Tag color | E6: Measurement (MM) | F6: Notes:
A7: 45915 | B7: Alasmidonta varicosa | C7: X466 | D7: Red | E7: 24
A8: 45915 | B8: Alasmidonta varicosa | C8: X467 | D8: Red | E8: 23
A9: 45915 | B9: Alasmidonta varicosa | C9: X468 | D9: Red | E9: 25
A10: 45915 | B10: Alasmidonta varicosa | C10: X469 | D10: Red | E10: 26
A11: 45915 | B11: Alasmidonta varicosa | C11: X470 | D11: Red | E11: 24
A12: 45915 | B12: Alasmidonta varicosa | C12: X471 | D12: Red | E12: 25
A13: 45915 | B13: Alasmidonta varicosa | C13: X472 | D13: Red | E13: 24
A14: 45915 | B14: Alasmidonta varicosa | C14: X473 | D14: Red | E14: 24
A15: 45915 | B15: Alasmidonta varicosa | C15: X474 | D15: Red | E15: 25
A16: 45915 | B16: Alasmidonta varicosa | C16: X475 | D16: Red | E16: 21
A17: 45915 | B17: Alasmidonta varicosa | C17: X476 | D17: Red | E17: 25
A18: 45915 | B18: Alasmidonta varicosa | C18: X477 | D18: Red | E18: 23
... A80: 45915 | B80: Alasmidonta varicosa | C80: X539 | D80: Red | E80: 22
A81: 45915 | B81: Alasmidonta varicosa | C81: X540 | D81: Red | E81: 20 | F81: *Accidentally kept behind at lab and not released
A82: 45922 | B82: Alasmidonta varicosa | C82: X752 | D82: Red | E82: 21
A83: 45924 | B83: Alasmidonta varicosa | C83: X770 | D83: Red | E83: 24
A84: 45924 | B84: Alasmidonta varicosa | C84: X771 | D84: Red | E84: 22
B85: Count: | C85: =COUNT(E7:E84) -> 78 | D85: Average: | E85: =AVERAGE(E7:E84) -> 23.282051 | F85: *77 A. varicosa released; 78 tagged in total, 1 accidentally kept behind at lab
A86: 45923 | B86: Elliptio complanata | C86: X764 | D86: Red | E86: 28
A87: 45923 | B87: Elliptio complanata | C87: X765 | D87: Red | E87: 22
A88: 45923 | B88: Elliptio complanata | C88: X766 | D88: Red | E88: 19
A89: 45923 | B89: Elliptio complanata | C89: X767 | D89: Red | E89: 22
A90: 45923 | B90: Elliptio complanata | C90: X768 | D90: Red | E90: 30
A91: 45926 | B91: Elliptio complanata | C91: X774 | D91: Red | E91: 66
A92: 45929 | B92: Elliptio complanata | C92: X775 | D92: Red | E92: 22
B93: Count: | C93: 7 | D93: Average: | E93: =AVERAGE(E86:E92) -> 29.857143 | F93: *7 E. complanata released; 7 tagged in total
A94: 45911 | B94: Elliptio fisheriana | C94: C412 | D94: Green | E94: 31 | F94: *Previously tagged; re-measured
A95: 45911 | B95: Elliptio fisheriana | C95: C484 | D95: Green | E95: 31 | F95: *Previously tagged; re-measured
A96: 45911 | B96: Elliptio fisheriana | C96: C413 | D96: Green | E96: 33 | F96: *Previously tagged; re-measured
A97: 45911 | B97: Elliptio fisheriana | C97: C431 | D97: Green | E97: 32 | F97: *Previously tagged; re-measured
A98: 45911 | B98: Elliptio fisheriana | C98: C430 | D98: Green | E98: 31 | F98: *Previously tagged; re-measured
A99: 45911 | B99: Elliptio fisheriana | C99: C497 | D99: Green | E99: 33 | F99: *Previously tagged; re-measured
A100: 45911 | B100: Elliptio fisheriana | C100: C429 | D100: Green | E100: 32 | F100: *Previously tagged; re-measured
A101: 45911 | B101: Elliptio fisheriana | C101: C417 | D101: Green | E101: 30 | F101: *Previously tagged; re-measured
A102: 45911 | B102: Elliptio fisheriana | C102: C451 | D102: Green | E102: 29 | F102: *Previously tagged; re-measured
...
